Workbook
Name pe0: Parametros!$B$2
Name omega: Parametros!$B$3
Name m_: Parametros!$B$4
Name e_base: Parametros!$B$5
Name pa: Parametros!$B$6
Name sref: Parametros!$B$7
Name tope: Parametros!$B$9
Name cc_bajo: Parametros!$B$19
Name cc_alto: Parametros!$B$20
Name sv_piso: Parametros!$B$21
Name c_ds: Parametros!$B$22

Sheet Leame
A1: Curva de resistencia Leps 2.0 del desmonte ROM de Antamina: datos, cálculos y curvas (memo de Stantec, 12 de octubre de 2026)
A3: Las celdas en azul de la hoja Parametros son las entradas; todo lo demás se calcula con fórmulas a partir de ellas (nombres definidos: pe0, omega, m_, e_base, sref, tope).
A4: Leps 2.0 (Cylwik et al. 2025, Ec. 26): τ = tan(φ′e=0 − ω·e)·(10pa)^(1−m)·σ′n^m; φ′s = atan(τ/σ′n). La curva se aplica con un tope de 42° en φ′s (τ ≤ σ′n·tan 42°).
A5: Unidades: esfuerzos en MPa; ángulos en grados.
A7: Hojas:
A8: Parametros: parámetros de la curva propuesta, hipótesis de curvatura y controles con la composición del DDE y la de LE2.
A9: Ensayos: los 120 ensayos de resistencia con su uso (ajuste, contraste, no usado), esfuerzos de falla, conversión de Leps 2.0 (fórmula) y corrección a e base (Ec. 27).
A10: Figuras: las seis figuras del memo como gráficos de Excel, con la misma numeración (datos y fórmulas en Datos_figuras).
A11: Curva: curva propuesta a e base, 0.55, 0.65 y perfiles A y V; tope de 42° en todas las curvas de Leps 2.0; banda de incertidumbre (sin tope); cotas de Indraratna et al. (1993) y Hawley y Cunning (2017); recta de 37°; sensibilidad del DDE; gráficos.
A12: phi1_vs_e: φ′1 de cada ensayo y por set contra e, φ′e=0 por set y su media (el nivel de la curva), con la recta de la curva propuesta, las envolventes de Leps (1970) y la cota de Indraratna et al. (1993).
A13: Hipotesis_m: φ′s según la hipótesis de curvatura (m del intervalo al 90 % y P10–P90 entre materiales de la base mundial, y m = 1 de Antamina sola como sensibilidad).
A14: Base_mundial: los ensayos de la base de Leps 2.0 (sin los censurados, como en el memo) frente a la curva evaluada a su propia e (Δφ′s) y conteos por rango de esfuerzo.
... A22: Informe final de estudio del DDE (Stantec 2026, IFF-115-G-0001 Rev. B) para la composición de control y la sensibilidad de 33°/30°.

Sheet Figuras
B1: Figuras del memorándum, recalculadas con las fórmulas de este libro (datos en Datos_figuras). La banda y la zona gris se dibujan con segmentos verticales; el rayado, con segmentos diagonales.
B3: Figura 1. φ′1 de cada set de Antamina frente a su e0 media, y la recta de la curva propuesta
B33: Figura 2. Curva propuesta y su banda de incertidumbre, con los ensayos del ajuste y la base mundial llevados a e base
B67: Figura 3. Contraste de la curva propuesta con los triaxiales CU de desmonte ROM no usados en el ajuste
B99: Figura 4. Índice de rotura de Marsal (1967) en los triaxiales drenados del ajuste
B125: Figura 5. Curva propuesta y su banda de incertidumbre en τ–σ′n
B157: Figura 6. (a) Relación de vacíos con la profundidad; (b) ángulo de fricción secante de la curva propuesta con cada supuesto

Sheet Parametros
A1: Parámetro | B1: Valor | C1: Unidad | D1: Nota
A2: φ′e=0, curva propuesta | B2: 48.470482 | C2: ° | D2: Media de φ′1 + 20·e0 de los 13 sets con m = 0.85, todos con igual peso (a33; ver phi1_vs_e)
A3: ω | B3: 20 | C3: ° | D3: Leps 2.0, Ec. 25
A4: m (curvatura) | B4: 0.85 | C4: - | D4: Sin sesgo en los ensayos mundiales de mayor esfuerzo (a31; IC 90 % 0.834–0.862)
A5: e base de colocación | B5: 0.45 | C5: - | D5: Desmonte ROM (sección 7 del memo)
A6: pa | B6: 0.1013 | C6: MPa | D6: Presión atmosférica
A7: 10·pa | B7: =10*pa | C7: MPa | D7: Esfuerzo de referencia
A8: φ′1 a e base | B8: =pe0-omega*e_base | C8: °
A9: Tope de φ′s | B9: 42 | C9: ° | D9: Ángulo secante máximo de la curva (bajo confinamiento; sección 7 del memo)
A10: Hipótesis de curvatura
A11: Hipótesis | B11: m | C11: φ′e=0 (°) | D11: Nota | E11: φ′e=0 P5 (°) | F11: φ′e=0 P95 (°)
A12: m P90 entre materiales | B12: 0.923 | C12: 48.240359 | D12: Nivel reajustado a los ensayos de Antamina con esa m (a33) | E12: 46.562344 | F12: 50.02548
A13: m alto (IC 90 %) | B13: 0.862 | C13: 48.430519 | D13: Nivel reajustado a los ensayos de Antamina con esa m (a33) | E13: 46.513065 | F13: 50.432216
A14: Curva propuesta | B14: 0.85 | C14: 48.470482 | D14: Nivel reajustado a los ensayos de Antamina con esa m (a33) | E14: 46.356522 | F14: 50.526617
A15: m bajo (IC 90 %) | B15: 0.834 | C15: 48.525148 | D15: Nivel reajustado a los ensayos de Antamina con esa m (a33) | E15: 46.398205 | F15: 50.633824
A16: m P10 entre materiales | B16: 0.787 | C16: 48.695345 | D16: Nivel reajustado a los ensayos de Antamina con esa m (a33) | E16: 46.30384 | F16: 51.124124
A17: Antamina sola (m = 1), sensibilidad | B17: 1 | C17: 48.028927 | D17: Nivel reajustado a los ensayos de Antamina con esa m (a33) | E17: 46.493273 | F17: 49.642245
A19: Cc perfil A, 0.2–0.8 MPa | B19: 0.074743382 | C19: - | D19: Edómetro de mármol suelto (a13)
A20: Cc perfil A, 1.2–4.8 MPa | B20: 0.11456125 | C20: - | D20: Edómetro de mármol suelto (a13)
A21: σ′v mínima de la ley del perfil A | B21: 0.05 | C21: MPa | D21: a13
A22: Peso del residuo del corte directo | B22: 1.6445849 | C22: - | D22: Iguala la sensibilidad al ángulo de ln q y ln τ (a9)
A23: Control: φ′e=0 con la composición del DDE (44/56) | B23: 48.421844 | C23: ° | D23: IFF-115-G-0001 Rev. B, Tabla 3-1: intrusivo y exoskarn 44 %, hornfels y mármol 56 % (repartido por igual)
A24: Control: φ′e=0 con la composición de LE2 | B24: 47.089939 | C24: ° | D24: MR2024, períodos ≥2035: mármol 37.8 %, hornfels 15.5 %, intrusivo 17.0 %, caliza y margas 29.6 % (sin ensayos; asimiladas al mármol)

Sheet Ensayos
A1: Fuente | B1: Set | C1: Ensayo (id) | D1: Litología | E1: Tipo | F1: Uso | G1: Motivo | H1: D (m) | I1: Dmax (mm) | J1: e0 | K1: σ′3 (MPa) | L1: σ′1 (MPa) | M1: σ′n (MPa) | N1: τ (MPa) | O1: φ′s (°) | P1: φ′s a e base (°) | Q1: φ′s predicha por la curva (mismo σ′n y e0 del ensayo) (°) | R1: Δφ′s ensayo − curva (°) | S1: εa (%) | T1: Criterio de falla | U1: Página | V1: φ′1 del ensayo a su e0 (°) | W1: φ′1 del ensayo a e base (°)
A2: G2012 | B2: G2012-MN-C | C2: Test 1 / Probeta 1 (σ'c = 5 kg/cm²) | D2: Mármol | E2: Triaxial CD | F2: Ajuste de la curva propuesta | H2: 1 | I2: 177.8 | J2: 0.31196845 | K2: 0.4903 | L2: 2.2712 | M2: =(L2+K2)/2-(L2-K2)/2*((SQRT(4*m_*(m_-1)*(L2-K2)^2+(L2+K2)^2)-(L2+K2))/(2*(m_-1)*(L2-K2))) | N2: =(L2-K2)/2*SQRT(1-((SQRT(4*m_*(m_-1)*(L2-K2)^2+(L2+K2)^2)-(L2+K2))/(2*(m_-1)*(L2-K2)))^2) | O2: =DEGREES(ATAN(N2/M2)) | P2: =O2-omega*(e_base-J2) | Q2: =DEGREES(ATAN(TAN(RADIANS(pe0-omega*J2))*(M2/sref)^(m_-1))) | R2: =O2-Q2 | S2: 17.27 | T2: CD: máximo desviador | U2: 7;29;27;28;17;10 | V2: =DEGREES(ATAN(TAN(RADIANS(O2))*(M2/sref)^(1-m_))) | W2: =V2-omega*(e_base-J2)
A3: G2012 | B3: G2012-MN-C | C3: Test 2 / Probeta 2 (σ'c = 5 kg/cm²) | D3: Mármol | E3: Triaxial CD | F3: Ajuste de la curva propuesta | H3: 1 | I3: 177.8 | J3: 0.31196845 | K3: 0.4903 | L3: 2.1928 | M3: =(L3+K3)/2-(L3-K3)/2*((SQRT(4*m_*(m_-1)*(L3-K3)^2+(L3+K3)^2)-(L3+K3))/(2*(m_-1)*(L3-K3))) | N3: =(L3-K3)/2*SQRT(1-((SQRT(4*m_*(m_-1)*(L3-K3)^2+(L3+K3)^2)-(L3+K3))/(2*(m_-1)*(L3-K3)))^2) | O3: =DEGREES(ATAN(N3/M3)) | P3: =O3-omega*(e_base-J3) | Q3: =DEGREES(ATAN(TAN(RADIANS(pe0-omega*J3))*(M3/sref)^(m_-1))) | R3: =O3-Q3 | S3: 18.26 | T3: CD: máximo desviador | U3: 7;40;27;28;17;10 | V3: =DEGREES(ATAN(TAN(RADIANS(O3))*(M3/sref)^(1-m_))) | W3: =V3-omega*(e_base-J3)
A4: G2012 | B4: G2012-MN-C | C4: Test 3 / Probeta 3 (σ'c = 10 kg/cm²) | D4: Mármol | E4: Triaxial CD | F4: Ajuste de la curva propuesta | H4: 1 | I4: 177.8 | J4: 0.31196845 | K4: 0.9807 | L4: 3.8972 | M4: =(L4+K4)/2-(L4-K4)/2*((SQRT(4*m_*(m_-1)*(L4-K4)^2+(L4+K4)^2)-(L4+K4))/(2*(m_-1)*(L4-K4))) | N4: =(L4-K4)/2*SQRT(1-((SQRT(4*m_*(m_-1)*(L4-K4)^2+(L4+K4)^2)-(L4+K4))/(2*(m_-1)*(L4-K4)))^2) | O4: =DEGREES(ATAN(N4/M4)) | P4: =O4-omega*(e_base-J4) | Q4: =DEGREES(ATAN(TAN(RADIANS(pe0-omega*J4))*(M4/sref)^(m_-1))) | R4: =O4-Q4 | S4: 18 | T4: CD: máximo desviador | U4: 7;52;27;28;17;10 | V4: =DEGREES(ATAN(TAN(RADIANS(O4))*(M4/sref)^(1-m_))) | W4: =V4-omega*(e_base-J4)
A5: G2012 | B5: G2012-MN-C | C5: Test 4 / Probeta 4 (σ'c = 20 kg/cm²) | D5: Mármol | E5: Triaxial CD | F5: Ajuste de la curva propuesta | H5: 1 | I5: 177.8 | J5: 0.31196845 | K5: 1.9613 | L5: 7.7786 | M5: =(L5+K5)/2-(L5-K5)/2*((SQRT(4*m_*(m_-1)*(L5-K5)^2+(L5+K5)^2)-(L5+K5))/(2*(m_-1)*(L5-K5))) | N5: =(L5-K5)/2*SQRT(1-((SQRT(4*m_*(m_-1)*(L5-K5)^2+(L5+K5)^2)-(L5+K5))/(2*(m_-1)*(L5-K5)))^2) | O5: =DEGREES(ATAN(N5/M5)) | P5: =O5-omega*(e_base-J5) | Q5: =DEGREES(ATAN(TAN(RADIANS(pe0-omega*J5))*(M5/sref)^(m_-1))) | R5: =O5-Q5 | S5: 19.59 | T5: CD: máximo desviador | U5: 7;55;27;28;17;10 | V5: =DEGREES(ATAN(TAN(RADIANS(O5))*(M5/sref)^(1-m_))) | W5: =V5-omega*(e_base-J5)
A6: G2012 | B6: G2012-MN-C | C6: Test 5 / Probeta 5 (σ'c = 20 kg/cm²) | D6: Mármol | E6: Triaxial CD | F6: Ajuste de la curva propuesta | H6: 1 | I6: 177.8 | J6: 0.31196845 | K6: 1.9613 | L6: 8.2905 | M6: =(L6+K6)/2-(L6-K6)/2*((SQRT(4*m_*(m_-1)*(L6-K6)^2+(L6+K6)^2)-(L6+K6))/(2*(m_-1)*(L6-K6))) | N6: =(L6-K6)/2*SQRT(1-((SQRT(4*m_*(m_-1)*(L6-K6)^2+(L6+K6)^2)-(L6+K6))/(2*(m_-1)*(L6-K6)))^2) | O6: =DEGREES(ATAN(N6/M6)) | P6: =O6-omega*(e_base-J6) | Q6: =DEGREES(ATAN(TAN(RADIANS(pe0-omega*J6))*(M6/sref)^(m_-1))) | R6: =O6-Q6 | S6: 17.78 | T6: CD: máximo desviador | U6: 7;70;27;28;17;10 | V6: =DEGREES(ATAN(TAN(RADIANS(O6))*(M6/sref)^(1-m_))) | W6: =V6-omega*(e_base-J6)
A7: G2021 | B7: G21-DESM-COMP | C7: II0471-E1 | D7: Mezcla | E7: Triaxial CD | F7: Ajuste de la curva propuesta | H7: 0.1524 | I7: 25.4 | J7: 0.32227338 | K7: 0.098 | L7: 0.381 | M7: =(L7+K7)/2-(L7-K7)/2*((SQRT(4*m_*(m_-1)*(L7-K7)^2+(L7+K7)^2)-(L7+K7))/(2*(m_-1)*(L7-K7))) | N7: =(L7-K7)/2*SQRT(1-((SQRT(4*m_*(m_-1)*(L7-K7)^2+(L7+K7)^2)-(L7+K7))/(2*(m_-1)*(L7-K7)))^2) | O7: =DEGREES(ATAN(N7/M7)) | P7: =O7-omega*(e_base-J7) | Q7: =DEGREES(ATAN(TAN(RADIANS(pe0-omega*J7))*(M7/sref)^(m_-1))) | R7: =O7-Q7 | S7: 3.99 | T7: CD: máximo desviador | U7: 20;108;46 | V7: =DEGREES(ATAN(TAN(RADIANS(O7))*(M7/sref)^(1-m_))) | W7: =V7-omega*(e_base-J7)
A8: G2021 | B8: G21-DESM-COMP | C8: II0471-E2 | D8: Mezcla | E8: Triaxial CD | F8: Ajuste de la curva propuesta | H8: 0.1524 | I8: 25.4 | J8: 0.32227338 | K8: 0.399 | L8: 1.917 | M8: =(L8+K8)/2-(L8-K8)/2*((SQRT(4*m_*(m_-1)*(L8-K8)^2+(L8+K8)^2)-(L8+K8))/(2*(m_-1)*(L8-K8))) | N8: =(L8-K8)/2*SQRT(1-((SQRT(4*m_*(m_-1)*(L8-K8)^2+(L8+K8)^2)-(L8+K8))/(2*(m_-1)*(L8-K8)))^2) | O8: =DEGREES(ATAN(N8/M8)) | P8: =O8-omega*(e_base-J8) | Q8: =DEGREES(ATAN(TAN(RADIANS(pe0-omega*J8))*(M8/sref)^(m_-1))) | R8: =O8-Q8 | S8: 20.21 | T8: CD: máximo desviador | U8: 20;109;46 | V8: =DEGREES(ATAN(TAN(RADIANS(O8))*(M8/sref)^(1-m_))) | W8: =V8-omega*(e_base-J8)
A9: G2021 | B9: G21-DESM-COMP | C9: II0471-E3 | D9: Mezcla | E9: Triaxial CD | F9: Ajuste de la curva propuesta | H9: 0.1524 | I9: 25.4 | J9: 0.3235653 | K9: 1.2 | L9: 5.847 | M9: =(L9+K9)/2-(L9-K9)/2*((SQRT(4*m_*(m_-1)*(L9-K9)^2+(L9+K9)^2)-(L9+K9))/(2*(m_-1)*(L9-K9))) | N9: =(L9-K9)/2*SQRT(1-((SQRT(4*m_*(m_-1)*(L9-K9)^2+(L9+K9)^2)-(L9+K9))/(2*(m_-1)*(L9-K9)))^2) | O9: =DEGREES(ATAN(N9/M9)) | P9: =O9-omega*(e_base-J9) | Q9: =DEGREES(ATAN(TAN(RADIANS(pe0-omega*J9))*(M9/sref)^(m_-1))) | R9: =O9-Q9 | S9: 12.09 | T9: CD: máximo desviador | U9: 20;110;46 | V9: =DEGREES(ATAN(TAN(RADIANS(O9))*(M9/sref)^(1-m_))) | W9: =V9-omega*(e_base-J9)
A10: W2022 | B10: HF-1.0m-IDIEM-mono | C10: Tabla 3 Hornfels Probeta 1 = IDIEM 1.555.677-B.2 PROBETA 1 | D10: Hornfels | E10: Triaxial CD | F10: Ajuste de la curva propuesta | H10: 1 | I10: 177.8 | J10: 0.33173131 | K10: 0.981 | L10: 4.878 | M10: =(L10+K10)/2-(L10-K10)/2*((SQRT(4*m_*(m_-1)*(L10-K10)^2+(L10+K10)^2)-(L10+K10))/(2*(m_-1)*(L10-K10))) | N10: =(L10-K10)/2*SQRT(1-((SQRT(4*m_*(m_-1)*(L10-K10)^2+(L10+K10)^2)-(L10+K10))/(2*(m_-1)*(L10-K10)))^2) | O10: =DEGREES(ATAN(N10/M10)) | P10: =O10-omega*(e_base-J10) | Q10: =DEGREES(ATAN(TAN(RADIANS(pe0-omega*J10))*(M10/sref)^(m_-1))) | R10: =O10-Q10 | S10: 13.13 | T10: CD: máximo desviador | U10: 10;233-236;62-63;41 | V10: =DEGREES(ATAN(TAN(RADIANS(O10))*(M10/sref)^(1-m_))) | W10: =V10-omega*(e_base-J10)
A11: W2022 | B11: HF-1.0m-IDIEM-mono | C11: Tabla 3 Hornfels Probeta 2 = IDIEM 1.555.677-B.2 PROBETA 2 | D11: Hornfels | E11: Triaxial CD | F11: Ajuste de la curva propuesta | H11: 1 | I11: 177.8 | J11: 0.33173131 | K11: 1.961 | L11: 11.021 | M11: =(L11+K11)/2-(L11-K11)/2*((SQRT(4*m_*(m_-1)*(L11-K11)^2+(L11+K11)^2)-(L11+K11))/(2*(m_-1)*(L11-K11))) | N11: =(L11-K11)/2*SQRT(1-((SQRT(4*m_*(m_-1)*(L11-K11)^2+(L11+K11)^2)-(L11+K11))/(2*(m_-1)*(L11-K11)))^2) | O11: =DEGREES(ATAN(N11/M11)) | P11: =O11-omega*(e_base-J11) | Q11: =DEGREES(ATAN(TAN(RADIANS(pe0-omega*J11))*(M11/sref)^(m_-1))) | R11: =O11-Q11 | S11: 19.04 | T11: CD: máximo desviador | U11: 10;238-243;62-63;41 | V11: =DEGREES(ATAN(TAN(RADIANS(O11))*(M11/sref)^(1-m_))) | W11: =V11-omega*(e_base-J11)
A12: W2022 | B12: HF-1.0m-IDIEM-mono | C12: Tabla 3 Hornfels Probeta 3 = IDIEM 1.555.677-B.2 PROBETA 3 | D12: Hornfels | E12: Triaxial CD | F12: Ajuste de la curva propuesta | H12: 1 | I12: 177.8 | J12: 0.33173131 | K12: 2.452 | L12: 14.382 | M12: =(L12+K12)/2-(L12-K12)/2*((SQRT(4*m_*(m_-1)*(L12-K12)^2+(L12+K12)^2)-(L12+K12))/(2*(m_-1)*(L12-K12))) | N12: =(L12-K12)/2*SQRT(1-((SQRT(4*m_*(m_-1)*(L12-K12)^2+(L12+K12)^2)-(L12+K12))/(2*(m_-1)*(L12-K12)))^2) | O12: =DEGREES(ATAN(N12/M12)) | P12: =O12-omega*(e_base-J12) | Q12: =DEGREES(ATAN(TAN(RADIANS(pe0-omega*J12))*(M12/sref)^(m_-1))) | R12: =O12-Q12 | S12: 17.83 | T12: CD: máximo desviador | U12: 10;245-250;62-63;41 | V12: =DEGREES(ATAN(TAN(RADIANS(O12))*(M12/sref)^(1-m_))) | W12: =V12-omega*(e_base-J12)
A13: W2022 | B13: HF-1.0m-IDIEM-cd | C13: Tabla 3 Hornfels Probeta 4 = IDIEM 1.555.677-E PROBETA 1 | D13: Hornfels | E13: Triaxial CD carga-descarga | F13: Ajuste de la curva propuesta | H13: 1 | I13: 177.8 | J13: 0.35743023 | K13: 0.981 | L13: 4.801 | M13: =(L13+K13)/2-(L13-K13)/2*((SQRT(4*m_*(m_-1)*(L13-K13)^2+(L13+K13)^2)-(L13+K13))/(2*(m_-1)*(L13-K13))) | N13: =(L13-K13)/2*SQRT(1-((SQRT(4*m_*(m_-1)*(L13-K13)^2+(L13+K13)^2)-(L13+K13))/(2*(m_-1)*(L13-K13)))^2) | O13: =DEGREES(ATAN(N13/M13)) | P13: =O13-omega*(e_base-J13) | Q13: =DEGREES(ATAN(TAN(RADIANS(pe0-omega*J13))*(M13/sref)^(m_-1))) | R13: =O13-Q13 | S13: 19.15 | T13: CD: máximo desviador | U13: 10;106-117;62-63;41 | V13: =DEGREES(ATAN(TAN(RADIANS(O13))*(M13/sref)^(1-m_))) | W13: =V13-omega*(e_base-J13)
... A23: I2025 | B23: Codisposal 1 (100% Intrusivo) | C23: Probeta 3 | D23: Intrusivo | E23: Triaxial CD | F23: Ajuste de la curva propuesta | H23: 1 | I23: 177.8 | J23: 0.28958641 | K23: 1.9613 | L23: 8.6867 | M23: =(L23+K23)/2-(L23-K23)/2*((SQRT(4*m_*(m_-1)*(L23-K23)^2+(L23+K23)^2)-(L23+K23))/(2*(m_-1)*(L23-K23))) | N23: =(L23-K23)/2*SQRT(1-((SQRT(4*m_*(m_-1)*(L23-K23)^2+(L23+K23)^2)-(L23+K23))/(2*(m_-1)*(L23-K23)))^2) | O23: =DEGREES(ATAN(N23/M23)) | P23: =O23-omega*(e_base-J23) | Q23: =DEGREES(ATAN(TAN(RADIANS(pe0-omega*J23))*(M23/sref)^(m_-1))) | R23: =O23-Q23 | S23: 11.18 | T23: CD: máximo desviador | U23: 22-27;28;8;29 | V23: =DEGREES(ATAN(TAN(RADIANS(O23))*(M23/sref)^(1-m_))) | W23: =V23-omega*(e_base-J23)
A24: A2024DS | B24: Ruma 02 | C24: LSDS Ruma 02 (H-1 al H-12) σn=300 | D24: Hornfels | E24: Corte directo CD | F24: Ajuste de la curva propuesta | H24: 0.31 | I24: 25.4 | J24: 0.33166667 | M24: 0.3 | N24: 0.2557 | O24: =DEGREES(ATAN(N24/M24)) | P24: =O24-omega*(e_base-J24) | Q24: =DEGREES(ATAN(TAN(RADIANS(pe0-omega*J24))*(M24/sref)^(m_-1))) | R24: =O24-Q24 | T24: CD: τ pico | V24: =DEGREES(ATAN(TAN(RADIANS(O24))*(M24/sref)^(1-m_))) | W24: =V24-omega*(e_base-J24)
A25: A2024DS | B25: Ruma 02 | C25: LSDS Ruma 02 (H-1 al H-12) σn=600 | D25: Hornfels | E25: Corte directo CD | F25: Ajuste de la curva propuesta | H25: 0.31 | I25: 25.4 | J25: 0.33166667 | M25: 0.6 | N25: 0.4761 | O25: =DEGREES(ATAN(N25/M25)) | P25: =O25-omega*(e_base-J25) | Q25: =DEGREES(ATAN(TAN(RADIANS(pe0-omega*J25))*(M25/sref)^(m_-1))) | R25: =O25-Q25 | T25: CD: τ pico | V25: =DEGREES(ATAN(TAN(RADIANS(O25))*(M25/sref)^(1-m_))) | W25: =V25-omega*(e_base-J25)
A26: A2024DS | B26: Ruma 02 | C26: LSDS Ruma 02 (H-1 al H-12) σn=1200 | D26: Hornfels | E26: Corte directo CD | F26: Ajuste de la curva propuesta | H26: 0.31 | I26: 25.4 | J26: 0.33166667 | M26: 1.2 | N26: 0.9981 | O26: =DEGREES(ATAN(N26/M26)) | P26: =O26-omega*(e_base-J26) | Q26: =DEGREES(ATAN(TAN(RADIANS(pe0-omega*J26))*(M26/sref)^(m_-1))) | R26: =O26-Q26 | T26: CD: τ pico | V26: =DEGREES(ATAN(TAN(RADIANS(O26))*(M26/sref)^(1-m_))) | W26: =V26-omega*(e_base-J26)
A27: A2024DS | B27: Ruma 03 / Fase 10 A | C27: LSDS Ruma 03 / Fase 10 A (I-1 al I-12) σn=300 | D27: Intrusivo | E27: Corte directo CD | F27: Ajuste de la curva propuesta | H27: 0.31 | I27: 25.4 | J27: 0.40968246 | M27: 0.3 | N27: 0.2281 | O27: =DEGREES(ATAN(N27/M27)) | P27: =O27-omega*(e_base-J27) | Q27: =DEGREES(ATAN(TAN(RADIANS(pe0-omega*J27))*(M27/sref)^(m_-1))) | R27: =O27-Q27 | T27: CD: τ pico | V27: =DEGREES(ATAN(TAN(RADIANS(O27))*(M27/sref)^(1-m_))) | W27: =V27-omega*(e_base-J27)
A28: A2024DS | B28: Ruma 03 / Fase 10 A | C28: LSDS Ruma 03 / Fase 10 A (I-1 al I-12) σn=600 | D28: Intrusivo | E28: Corte directo CD | F28: Ajuste de la curva propuesta | H28: 0.31 | I28: 25.4 | J28: 0.40968246 | M28: 0.6 | N28: 0.4681 | O28: =DEGREES(ATAN(N28/M28)) | P28: =O28-omega*(e_base-J28) | Q28: =DEGREES(ATAN(TAN(RADIANS(pe0-omega*J28))*(M28/sref)^(m_-1))) | R28: =O28-Q28 | T28: CD: τ pico | V28: =DEGREES(ATAN(TAN(RADIANS(O28))*(M28/sref)^(1-m_))) | W28: =V28-omega*(e_base-J28)
A29: A2024DS | B29: Ruma 03 / Fase 10 A | C29: LSDS Ruma 03 / Fase 10 A (I-1 al I-12) σn=1200 | D29: Intrusivo | E29: Corte directo CD | F29: Ajuste de la curva propuesta | H29: 0.31 | I29: 25.4 | J29: 0.40968246 | M29: 1.2 | N29: 0.9451 | O29: =DEGREES(ATAN(N29/M29)) | P29: =O29-omega*(e_base-J29) | Q29: =DEGREES(ATAN(TAN(RADIANS(pe0-omega*J29))*(M29/sref)^(m_-1))) | R29: =O29-Q29 | T29: CD: τ pico | V29: =DEGREES(ATAN(TAN(RADIANS(O29))*(M29/sref)^(1-m_))) | W29: =V29-omega*(e_base-J29)
A30: A2024DS | B30: Ruma 01 | C30: LSDS Ruma 01 (M-1 al M-13) σn=300 | D30: Mármol | E30: Corte directo CD | F30: Ajuste de la curva propuesta | H30: 0.31 | I30: 25.4 | J30: 0.26202474 | M30: 0.3 | N30: 0.2195 | O30: =DEGREES(ATAN(N30/M30)) | P30: =O30-omega*(e_base-J30) | Q30: =DEGREES(ATAN(TAN(RADIANS(pe0-omega*J30))*(M30/sref)^(m_-1))) | R30: =O30-Q30 | T30: CD: τ pico | V30: =DEGREES(ATAN(TAN(RADIANS(O30))*(M30/sref)^(1-m_))) | W30: =V30-omega*(e_base-J30)
A31: A2024DS | B31: Ruma 01 | C31: LSDS Ruma 01 (M-1 al M-13) σn=600 | D31: Mármol | E31: Corte directo CD | F31: Ajuste de la curva propuesta | H31: 0.31 | I31: 25.4 | J31: 0.26202474 | M31: 0.6 | N31: 0.4695 | O31: =DEGREES(ATAN(N31/M31)) | P31: =O31-omega*(e_base-J31) | Q31: =DEGREES(ATAN(TAN(RADIANS(pe0-omega*J31))*(M31/sref)^(m_-1))) | R31: =O31-Q31 | T31: CD: τ pico | V31: =DEGREES(ATAN(TAN(RADIANS(O31))*(M31/sref)^(1-m_))) | W31: =V31-omega*(e_base-J31)
A32: A2024DS | B32: Ruma 01 | C32: LSDS Ruma 01 (M-1 al M-13) σn=1200 | D32: Mármol | E32: Corte directo CD | F32: Ajuste de la curva propuesta | H32: 0.31 | I32: 25.4 | J32: 0.26202474 | M32: 1.2 | N32: 0.9843 | O32: =DEGREES(ATAN(N32/M32)) | P32: =O32-omega*(e_base-J32) | Q32: =DEGREES(ATAN(TAN(RADIANS(pe0-omega*J32))*(M32/sref)^(m_-1))) | R32: =O32-Q32 | T32: CD: τ pico | V32: =DEGREES(ATAN(TAN(RADIANS(O32))*(M32/sref)^(1-m_))) | W32: =V32-omega*(e_base-J32)
A33: A2024DS | B33: Pila 01 (Mármol + Hornfels) | C33: LSDS Pila 01 (Mármol + Hornfels) σn=300 | D33: Mezcla | E33: Corte directo CD | F33: Ajuste de la curva propuesta | H33: 0.31 | I33: 25.4 | J33: 0.32557307 | M33: 0.3 | N33: 0.3563 | O33: =DEGREES(ATAN(N33/M33)) | P33: =O33-omega*(e_base-J33) | Q33: =DEGREES(ATAN(TAN(RADIANS(pe0-omega*J33))*(M33/sref)^(m_-1))) | R33: =O33-Q33 | T33: CD: τ pico | V33: =DEGREES(ATAN(TAN(RADIANS(O33))*(M33/sref)^(1-m_))) | W33: =V33-omega*(e_base-J33)
A34: A2024DS | B34: Pila 01 (Mármol + Hornfels) | C34: LSDS Pila 01 (Mármol + Hornfels) σn=600 | D34: Mezcla | E34: Corte directo CD | F34: Ajuste de la curva propuesta | H34: 0.31 | I34: 25.4 | J34: 0.32557307 | M34: 0.6 | N34: 0.6253 | O34: =DEGREES(ATAN(N34/M34)) | P34: =O34-omega*(e_base-J34) | Q34: =DEGREES(ATAN(TAN(RADIANS(pe0-omega*J34))*(M34/sref)^(m_-1))) | R34: =O34-Q34 | T34: CD: τ pico | V34: =DEGREES(ATAN(TAN(RADIANS(O34))*(M34/sref)^(1-m_))) | W34: =V34-omega*(e_base-J34)
A35: A2024DS | B35: Pila 01 (Mármol + Hornfels) | C35: LSDS Pila 01 (Mármol + Hornfels) σn=1000 | D35: Mezcla | E35: Corte directo CD | F35: Ajuste de la curva propuesta | H35: 0.31 | I35: 25.4 | J35: 0.32557307 | M35: 1 | N35: 0.9473 | O35: =DEGREES(ATAN(N35/M35)) | P35: =O35-omega*(e_base-J35) | Q35: =DEGREES(ATAN(TAN(RADIANS(pe0-omega*J35))*(M35/sref)^(m_-1))) | R35: =O35-Q35 | T35: CD: τ pico | V35: =DEGREES(ATAN(TAN(RADIANS(O35))*(M35/sref)^(1-m_))) | W35: =V35-omega*(e_base-J35)
... A38: A2024DS | B38: Pila 02 (Intrusivo) | C38: LSDS Pila 02 (Intrusivo) σn=1200 | D38: Intrusivo | E38: Corte directo CD | F38: Ajuste de la curva propuesta | H38: 0.31 | I38: 25.4 | J38: 0.47897324 | M38: 1.2 | N38: 1.0192 | O38: =DEGREES(ATAN(N38/M38)) | P38: =O38-omega*(e_base-J38) | Q38: =DEGREES(ATAN(TAN(RADIANS(pe0-omega*J38))*(M38/sref)^(m_-1))) | R38: =O38-Q38 | T38: CD: τ pico | V38: =DEGREES(ATAN(TAN(RADIANS(O38))*(M38/sref)^(1-m_))) | W38: =V38-omega*(e_base-J38)
A39: G2010 | B39: G2010-A-MN-2.8in | C39: GL-481-09 Prueba Nº 1 (σ3c=324 kPa) | D39: Mármol | E39: Triaxial CU | F39: Contraste | G39: triaxial no drenado (CU), máximo desviador | H39: 0.0714 | I39: 9.5 | J39: 0.29 | K39: 0.619 | L39: 2.838 | M39: =(L39+K39)/2-(L39-K39)/2*((SQRT(4*m_*(m_-1)*(L39-K39)^2+(L39+K39)^2)-(L39+K39))/(2*(m_-1)*(L39-K39))) | N39: =(L39-K39)/2*SQRT(1-((SQRT(4*m_*(m_-1)*(L39-K39)^2+(L39+K39)^2)-(L39+K39))/(2*(m_-1)*(L39-K39)))^2) | O39: =DEGREES(ATAN(N39/M39)) | P39: =O39-omega*(e_base-J39) | Q39: =DEGREES(ATAN(TAN(RADIANS(pe0-omega*J39))*(M39/sref)^(m_-1))) | R39: =O39-Q39 | S39: 8.3 | T39: CU: máximo desviador (la fuente no permite máxima oblicuidad) | U39: 82;84;8;9;49 | V39: =DEGREES(ATAN(TAN(RADIANS(O39))*(M39/sref)^(1-m_))) | W39: =V39-omega*(e_base-J39)
A40: G2010 | B40: G2010-A-MN-2.8in | C40: GL-481-09 Prueba Nº 2 (σ3c=788 kPa) | D40: Mármol | E40: Triaxial CU | F40: Contraste | G40: triaxial no drenado (CU), máximo desviador | H40: 0.0715 | I40: 9.5 | J40: 0.295 | K40: 0.717 | L40: 3.111 | M40: =(L40+K40)/2-(L40-K40)/2*((SQRT(4*m_*(m_-1)*(L40-K40)^2+(L40+K40)^2)-(L40+K40))/(2*(m_-1)*(L40-K40))) | N40: =(L40-K40)/2*SQRT(1-((SQRT(4*m_*(m_-1)*(L40-K40)^2+(L40+K40)^2)-(L40+K40))/(2*(m_-1)*(L40-K40)))^2) | O40: =DEGREES(ATAN(N40/M40)) | P40: =O40-omega*(e_base-J40) | Q40: =DEGREES(ATAN(TAN(RADIANS(pe0-omega*J40))*(M40/sref)^(m_-1))) | R40: =O40-Q40 | S40: 7.6 | T40: CU: máximo desviador (la fuente no permite máxima oblicuidad) | U40: 82;84;8;9;49 | V40: =DEGREES(ATAN(TAN(RADIANS(O40))*(M40/sref)^(1-m_))) | W40: =V40-omega*(e_base-J40)
A41: G2010 | B41: G2010-A-MN-2.8in | C41: GL-481-09 Prueba Nº 3 (σ3c=1570 kPa) | D41: Mármol | E41: Triaxial CU | F41: Contraste | G41: triaxial no drenado (CU), máximo desviador | H41: 0.0714 | I41: 9.5 | J41: 0.29 | K41: 0.869 | L41: 3.606 | M41: =(L41+K41)/2-(L41-K41)/2*((SQRT(4*m_*(m_-1)*(L41-K41)^2+(L41+K41)^2)-(L41+K41))/(2*(m_-1)*(L41-K41))) | N41: =(L41-K41)/2*SQRT(1-((SQRT(4*m_*(m_-1)*(L41-K41)^2+(L41+K41)^2)-(L41+K41))/(2*(m_-1)*(L41-K41)))^2) | O41: =DEGREES(ATAN(N41/M41)) | P41: =O41-omega*(e_base-J41) | Q41: =DEGREES(ATAN(TAN(RADIANS(pe0-omega*J41))*(M41/sref)^(m_-1))) | R41: =O41-Q41 | S41: 5.3 | T41: CU: máximo desviador (la fuente no permite máxima oblicuidad) | U41: 82;84;8;9;49 | V41: =DEGREES(ATAN(TAN(RADIANS(O41))*(M41/sref)^(1-m_))) | W41: =V41-omega*(e_base-J41)
A42: G2010 | B42: G2010-A-HG-2.8in | C42: GL-482-09 Prueba Nº 1 (σ3c=393 kPa) | D42: Hornfels | E42: Triaxial CU | F42: Contraste | G42: triaxial no drenado (CU), máximo desviador | H42: 0.0717 | I42: 9.5 | J42: 0.377 | K42: 0.216 | L42: 0.922 | M42: =(L42+K42)/2-(L42-K42)/2*((SQRT(4*m_*(m_-1)*(L42-K42)^2+(L42+K42)^2)-(L42+K42))/(2*(m_-1)*(L42-K42))) | N42: =(L42-K42)/2*SQRT(1-((SQRT(4*m_*(m_-1)*(L42-K42)^2+(L42+K42)^2)-(L42+K42))/(2*(m_-1)*(L42-K42)))^2) | O42: =DEGREES(ATAN(N42/M42)) | P42: =O42-omega*(e_base-J42) | Q42: =DEGREES(ATAN(TAN(RADIANS(pe0-omega*J42))*(M42/sref)^(m_-1))) | R42: =O42-Q42 | S42: 1.9 | T42: CU: máximo desviador (la fuente no permite máxima oblicuidad) | U42: 87;89;8;9;49 | V42: =DEGREES(ATAN(TAN(RADIANS(O42))*(M42/sref)^(1-m_))) | W42: =V42-omega*(e_base-J42)
A43: G2010 | B43: G2010-A-HG-2.8in | C43: GL-482-09 Prueba Nº 2 (σ3c=786 kPa) | D43: Hornfels | E43: Triaxial CU | F43: Contraste | G43: triaxial no drenado (CU), máximo desviador | H43: 0.0717 | I43: 9.5 | J43: 0.377 | K43: 0.303 | L43: 1.207 | M43: =(L43+K43)/2-(L43-K43)/2*((SQRT(4*m_*(m_-1)*(L43-K43)^2+(L43+K43)^2)-(L43+K43))/(2*(m_-1)*(L43-K43))) | N43: =(L43-K43)/2*SQRT(1-((SQRT(4*m_*(m_-1)*(L43-K43)^2+(L43+K43)^2)-(L43+K43))/(2*(m_-1)*(L43-K43)))^2) | O43: =DEGREES(ATAN(N43/M43)) | P43: =O43-omega*(e_base-J43) | Q43: =DEGREES(ATAN(TAN(RADIANS(pe0-omega*J43))*(M43/sref)^(m_-1))) | R43: =O43-Q43 | S43: 1.8 | T43: CU: máximo desviador (la fuente no permite máxima oblicuidad) | U43: 87;89;8;9;49 | V43: =DEGREES(ATAN(TAN(RADIANS(O43))*(M43/sref)^(1-m_))) | W43: =V43-omega*(e_base-J43)
A44: G2010 | B44: G2010-A-HG-2.8in | C44: GL-482-09 Prueba Nº 3 (σ3c=1577 kPa) | D44: Hornfels | E44: Triaxial CU | F44: Contraste | G44: triaxial no drenado (CU), máximo desviador | H44: 0.0717 | I44: 9.5 | J44: 0.377 | K44: 0.535 | L44: 2.071 | M44: =(L44+K44)/2-(L44-K44)/2*((SQRT(4*m_*(m_-1)*(L44-K44)^2+(L44+K44)^2)-(L44+K44))/(2*(m_-1)*(L44-K44))) | N44: =(L44-K44)/2*SQRT(1-((SQRT(4*m_*(m_-1)*(L44-K44)^2+(L44+K44)^2)-(L44+K44))/(2*(m_-1)*(L44-K44)))^2) | O44: =DEGREES(ATAN(N44/M44)) | P44: =O44-omega*(e_base-J44) | Q44: =DEGREES(ATAN(TAN(RADIANS(pe0-omega*J44))*(M44/sref)^(m_-1))) | R44: =O44-Q44 | S44: 2.5 | T44: CU: máximo desviador (la fuente no permite máxima oblicuidad) | U44: 87;89;8;9;49 | V44: =DEGREES(ATAN(TAN(RADIANS(O44))*(M44/sref)^(1-m_))) | W44: =V44-omega*(e_base-J44)
A45: G2010 | B45: G2010-A-INT-2.8in | C45: GL-483-09 Prueba Nº 1 (σ3c=394 kPa) | D45: Intrusivo | E45: Triaxial CU | F45: Contraste | G45: triaxial no drenado (CU), máximo desviador | H45: 0.0717 | I45: 9.5 | J45: 0.434 | K45: 0.261 | L45: 1.13 | M45: =(L45+K45)/2-(L45-K45)/2*((SQRT(4*m_*(m_-1)*(L45-K45)^2+(L45+K45)^2)-(L45+K45))/(2*(m_-1)*(L45-K45))) | N45: =(L45-K45)/2*SQRT(1-((SQRT(4*m_*(m_-1)*(L45-K45)^2+(L45+K45)^2)-(L45+K45))/(2*(m_-1)*(L45-K45)))^2) | O45: =DEGREES(ATAN(N45/M45)) | P45: =O45-omega*(e_base-J45) | Q45: =DEGREES(ATAN(TAN(RADIANS(pe0-omega*J45))*(M45/sref)^(m_-1))) | R45: =O45-Q45 | S45: 1.6 | T45: CU: máximo desviador (la fuente no permite máxima oblicuidad) | U45: 92;94;8;9;49 | V45: =DEGREES(ATAN(TAN(RADIANS(O45))*(M45/sref)^(1-m_))) | W45: =V45-omega*(e_base-J45)
A46: G2010 | B46: G2010-A-INT-2.8in | C46: GL-483-09 Prueba Nº 2 (σ3c=788 kPa) | D46: Intrusivo | E46: Triaxial CU | F46: Contraste | G46: triaxial no drenado (CU), máximo desviador | H46: 0.0717 | I46: 9.5 | J46: 0.434 | K46: 0.393 | L46: 1.578 | M46: =(L46+K46)/2-(L46-K46)/2*((SQRT(4*m_*(m_-1)*(L46-K46)^2+(L46+K46)^2)-(L46+K46))/(2*(m_-1)*(L46-K46))) | N46: =(L46-K46)/2*SQRT(1-((SQRT(4*m_*(m_-1)*(L46-K46)^2+(L46+K46)^2)-(L46+K46))/(2*(m_-1)*(L46-K46)))^2) | O46: =DEGREES(ATAN(N46/M46)) | P46: =O46-omega*(e_base-J46) | Q46: =DEGREES(ATAN(TAN(RADIANS(pe0-omega*J46))*(M46/sref)^(m_-1))) | R46: =O46-Q46 | S46: 1.9 | T46: CU: máximo desviador (la fuente no permite máxima oblicuidad) | U46: 92;94;8;9;49 | V46: =DEGREES(ATAN(TAN(RADIANS(O46))*(M46/sref)^(1-m_))) | W46: =V46-omega*(e_base-J46)
A47: G2010 | B47: G2010-A-INT-2.8in | C47: GL-483-09 Prueba Nº 3 (σ3c=1570 kPa) | D47: Intrusivo | E47: Triaxial CU | F47: Contraste | G47: triaxial no drenado (CU), máximo desviador | H47: 0.0717 | I47: 9.5 | J47: 0.434 | K47: 0.528 | L47: 1.934 | M47: =(L47+K47)/2-(L47-K47)/2*((SQRT(4*m_*(m_-1)*(L47-K47)^2+(L47+K47)^2)-(L47+K47))/(2*(m_-1)*(L47-K47))) | N47: =(L47-K47)/2*SQRT(1-((SQRT(4*m_*(m_-1)*(L47-K47)^2+(L47+K47)^2)-(L47+K47))/(2*(m_-1)*(L47-K47)))^2) | O47: =DEGREES(ATAN(N47/M47)) | P47: =O47-omega*(e_base-J47) | Q47: =DEGREES(ATAN(TAN(RADIANS(pe0-omega*J47))*(M47/sref)^(m_-1))) | R47: =O47-Q47 | S47: 1.7 | T47: CU: máximo desviador (la fuente no permite máxima oblicuidad) | U47: 92;94;8;9;49 | V47: =DEGREES(ATAN(TAN(RADIANS(O47))*(M47/sref)^(1-m_))) | W47: =V47-omega*(e_base-J47)
A48: G2010 | B48: G2010-A-EXO-2.8in | C48: GL-484-09 Prueba Nº 1 (σ3c=394 kPa) | D48: Skarn | E48: Triaxial CU | F48: Contraste | G48: triaxial no drenado (CU), máximo desviador | H48: 0.0714 | I48: 9.5 | J48: 0.532 | K48: 0.193 | L48: 0.565 | M48: =(L48+K48)/2-(L48-K48)/2*((SQRT(4*m_*(m_-1)*(L48-K48)^2+(L48+K48)^2)-(L48+K48))/(2*(m_-1)*(L48-K48))) | N48: =(L48-K48)/2*SQRT(1-((SQRT(4*m_*(m_-1)*(L48-K48)^2+(L48+K48)^2)-(L48+K48))/(2*(m_-1)*(L48-K48)))^2) | O48: =DEGREES(ATAN(N48/M48)) | P48: =O48-omega*(e_base-J48) | Q48: =DEGREES(ATAN(TAN(RADIANS(pe0-omega*J48))*(M48/sref)^(m_-1))) | R48: =O48-Q48 | S48: 1.1 | T48: CU: máximo desviador (la fuente no permite máxima oblicuidad) | U48: 97;99;8;9;49 | V48: =DEGREES(ATAN(TAN(RADIANS(O48))*(M48/sref)^(1-m_))) | W48: =V48-omega*(e_base-J48)
A49: G2010 | B49: G2010-A-EXO-2.8in | C49: GL-484-09 Prueba Nº 2 (σ3c=787 kPa) | D49: Skarn | E49: Triaxial CU | F49: Contraste | G49: triaxial no drenado (CU), máximo desviador | H49: 0.0714 | I49: 9.5 | J49: 0.531 | K49: 0.317 | L49: 0.884 | M49: =(L49+K49)/2-(L49-K49)/2*((SQRT(4*m_*(m_-1)*(L49-K49)^2+(L49+K49)^2)-(L49+K49))/(2*(m_-1)*(L49-K49))) | N49: =(L49-K49)/2*SQRT(1-((SQRT(4*m_*(m_-1)*(L49-K49)^2+(L49+K49)^2)-(L49+K49))/(2*(m_-1)*(L49-K49)))^2) | O49: =DEGREES(ATAN(N49/M49)) | P49: =O49-omega*(e_base-J49) | Q49: =DEGREES(ATAN(TAN(RADIANS(pe0-omega*J49))*(M49/sref)^(m_-1))) | R49: =O49-Q49 | S49: 1.2 | T49: CU: máximo desviador (la fuente no permite máxima oblicuidad) | U49: 97;99;8;9;49 | V49: =DEGREES(ATAN(TAN(RADIANS(O49))*(M49/sref)^(1-m_))) | W49: =V49-omega*(e_base-J49)
A50: G2010 | B50: G2010-A-EXO-2.8in | C50: GL-484-09 Prueba Nº 3 (σ3c=1573 kPa) | D50: Skarn | E50: Triaxial CU | F50: Contraste | G50: triaxial no drenado (CU), máximo desviador | H50: 0.0714 | I50: 9.5 | J50: 0.532 | K50: 0.486 | L50: 1.409 | M50: =(L50+K50)/2-(L50-K50)/2*((SQRT(4*m_*(m_-1)*(L50-K50)^2+(L50+K50)^2)-(L50+K50))/(2*(m_-1)*(L50-K50))) | N50: =(L50-K50)/2*SQRT(1-((SQRT(4*m_*(m_-1)*(L50-K50)^2+(L50+K50)^2)-(L50+K50))/(2*(m_-1)*(L50-K50)))^2) | O50: =DEGREES(ATAN(N50/M50)) | P50: =O50-omega*(e_base-J50) | Q50: =DEGREES(ATAN(TAN(RADIANS(pe0-omega*J50))*(M50/sref)^(m_-1))) | R50: =O50-Q50 | S50: 1.3 | T50: CU: máximo desviador (la fuente no permite máxima oblicuidad) | U50: 97;99;8;9;49 | V50: =DEGREES(ATAN(TAN(RADIANS(O50))*(M50/sref)^(1-m_))) | W50: =V50-omega*(e_base-J50)
... A59: G2010 | B59: G2010-A-EXO-4in | C59: GL-484-09 Prueba Nº 3 (σ3c=783 kPa) | D59: Skarn | E59: Triaxial CU | F59: Contraste | G59: triaxial no drenado (CU), máximo desviador | H59: 0.1011 | I59: 15.9 | J59: 0.703 | K59: 0.358 | L59: 1.019 | M59: =(L59+K59)/2-(L59-K59)/2*((SQRT(4*m_*(m_-1)*(L59-K59)^2+(L59+K59)^2)-(L59+K59))/(2*(m_-1)*(L59-K59))) | N59: =(L59-K59)/2*SQRT(1-((SQRT(4*m_*(m_-1)*(L59-K59)^2+(L59+K59)^2)-(L59+K59))/(2*(m_-1)*(L59-K59)))^2) | O59: =DEGREES(ATAN(N59/M59)) | P59: =O59-omega*(e_base-J59) | Q59: =DEGREES(ATAN(TAN(RADIANS(pe0-omega*J59))*(M59/sref)^(m_-1))) | R59: =O59-Q59 | S59: 1.2 | T59: CU: máximo desviador (la fuente no permite máxima oblicuidad) | U59: 112;114;8;9;49 | V59: =DEGREES(ATAN(TAN(RADIANS(O59))*(M59/sref)^(1-m_))) | W59: =V59-omega*(e_base-J59)
...

Sheet Curva
A1: σ′n (MPa) | B1: Zona | C1: τ curva, con tope (MPa) | D1: φ′s curva, con tope (°) | E1: φ′s banda inf. (°) | F1: φ′s banda sup. (°) | G1: τ banda inf. (MPa) | H1: τ banda sup. (MPa) | I1: τ e = 0.55 | J1: τ e = 0.65 | K1: e perfil A | L1: τ perfil A | M1: e perfil V | N1: τ perfil V | O1: φ′s Indraratna (°) | P1: φ′s Hawley y Cunning (°) | Q1: τ Indraratna | R1: τ Hawley y Cunning | S1: τ 37° (MPa) | T1: φ′ sensibilidad DDE (°)
A2: 0.01 | B2: con ensayos de Antamina | C2: =MIN(TAN(RADIANS(pe0-omega*e_base))*sref^(1-m_)*A2^m_,A2*TAN(RADIANS(tope))) | D2: =DEGREES(ATAN(C2/A2)) | E2: =MIN(DEGREES(ATAN(TAN(RADIANS(Parametros!$E$12-omega*e_base))*(A2/sref)^(Parametros!$B$12-1))),DEGREES(ATAN(TAN(RADIANS(Parametros!$E$13-omega*e_base))*(A2/sref)^(Parametros!$B$13-1))),DEGREES(ATAN(TAN(RADIANS(Parametros!$E$14-omega*e_base))*(A2/sref)^(Parametros!$B$14-1))),DEGREES(ATAN(TAN(RADIANS(Parametros!$E$15-omega*e_base))*(A2/sref)^(Parametros!$B$15-1))),DEGREES(ATAN(TAN(RADIANS(Parametros!$E$16-omega*e_base))*(A2/sref)^(Parametros!$B$16-1)))) | F2: =MAX(DEGREES(ATAN(TAN(RADIANS(Parametros!$F$12-omega*e_base))*(A2/sref)^(Parametros!$B$12-1))),DEGREES(ATAN(TAN(RADIANS(Parametros!$F$13-omega*e_base))*(A2/sref)^(Parametros!$B$13-1))),DEGREES(ATAN(TAN(RADIANS(Parametros!$F$14-omega*e_base))*(A2/sref)^(Parametros!$B$14-1))),DEGREES(ATAN(TAN(RADIANS(Parametros!$F$15-omega*e_base))*(A2/sref)^(Parametros!$B$15-1))),DEGREES(ATAN(TAN(RADIANS(Parametros!$F$16-omega*e_base))*(A2/sref)^(Parametros!$B$16-1)))) | G2: =A2*TAN(RADIANS(E2)) | H2: =A2*TAN(RADIANS(F2)) | I2: =MIN(TAN(RADIANS(pe0-omega*0.55))*sref^(1-m_)*A2^m_,A2*TAN(RADIANS(tope))) | J2: =MIN(TAN(RADIANS(pe0-omega*0.65))*sref^(1-m_)*A2^m_,A2*TAN(RADIANS(tope))) | K2: =IF(MAX(A2,sv_piso)<=1,e_base-cc_bajo*LOG10(MAX(A2,sv_piso)/sv_piso),e_base-cc_bajo*LOG10(1/sv_piso)-cc_alto*LOG10(A2)) | L2: =MIN(TAN(RADIANS(pe0-omega*K2))*sref^(1-m_)*A2^m_,A2*TAN(RADIANS(tope))) | M2: 0.4494 | N2: =MIN(TAN(RADIANS(pe0-omega*M2))*sref^(1-m_)*A2^m_,A2*TAN(RADIANS(tope))) | O2: =DEGREES(ATAN(TAN(RADIANS(33))*(A2/sref)^(0.9-1))) | P2: =DEGREES(ATAN(1.446*(A2*1000)^0.898/(A2*1000))) | Q2: =A2*TAN(RADIANS(O2)) | R2: =A2*TAN(RADIANS(P2)) | S2: =A2*TAN(RADIANS(37))
A3: 0.02 | B3: con ensayos de Antamina | C3: =MIN(TAN(RADIANS(pe0-omega*e_base))*sref^(1-m_)*A3^m_,A3*TAN(RADIANS(tope))) | D3: =DEGREES(ATAN(C3/A3)) | E3: =MIN(DEGREES(ATAN(TAN(RADIANS(Parametros!$E$12-omega*e_base))*(A3/sref)^(Parametros!$B$12-1))),DEGREES(ATAN(TAN(RADIANS(Parametros!$E$13-omega*e_base))*(A3/sref)^(Parametros!$B$13-1))),DEGREES(ATAN(TAN(RADIANS(Parametros!$E$14-omega*e_base))*(A3/sref)^(Parametros!$B$14-1))),DEGREES(ATAN(TAN(RADIANS(Parametros!$E$15-omega*e_base))*(A3/sref)^(Parametros!$B$15-1))),DEGREES(ATAN(TAN(RADIANS(Parametros!$E$16-omega*e_base))*(A3/sref)^(Parametros!$B$16-1)))) | F3: =MAX(DEGREES(ATAN(TAN(RADIANS(Parametros!$F$12-omega*e_base))*(A3/sref)^(Parametros!$B$12-1))),DEGREES(ATAN(TAN(RADIANS(Parametros!$F$13-omega*e_base))*(A3/sref)^(Parametros!$B$13-1))),DEGREES(ATAN(TAN(RADIANS(Parametros!$F$14-omega*e_base))*(A3/sref)^(Parametros!$B$14-1))),DEGREES(ATAN(TAN(RADIANS(Parametros!$F$15-omega*e_base))*(A3/sref)^(Parametros!$B$15-1))),DEGREES(ATAN(TAN(RADIANS(Parametros!$F$16-omega*e_base))*(A3/sref)^(Parametros!$B$16-1)))) | G3: =A3*TAN(RADIANS(E3)) | H3: =A3*TAN(RADIANS(F3)) | I3: =MIN(TAN(RADIANS(pe0-omega*0.55))*sref^(1-m_)*A3^m_,A3*TAN(RADIANS(tope))) | J3: =MIN(TAN(RADIANS(pe0-omega*0.65))*sref^(1-m_)*A3^m_,A3*TAN(RADIANS(tope))) | K3: =IF(MAX(A3,sv_piso)<=1,e_base-cc_bajo*LOG10(MAX(A3,sv_piso)/sv_piso),e_base-cc_bajo*LOG10(1/sv_piso)-cc_alto*LOG10(A3)) | L3: =MIN(TAN(RADIANS(pe0-omega*K3))*sref^(1-m_)*A3^m_,A3*TAN(RADIANS(tope))) | M3: 0.4488 | N3: =MIN(TAN(RADIANS(pe0-omega*M3))*sref^(1-m_)*A3^m_,A3*TAN(RADIANS(tope))) | O3: =DEGREES(ATAN(TAN(RADIANS(33))*(A3/sref)^(0.9-1))) | P3: =DEGREES(ATAN(1.446*(A3*1000)^0.898/(A3*1000))) | Q3: =A3*TAN(RADIANS(O3)) | R3: =A3*TAN(RADIANS(P3)) | S3: =A3*TAN(RADIANS(37))
A4: 0.03 | B4: con ensayos de Antamina | C4: =MIN(TAN(RADIANS(pe0-omega*e_base))*sref^(1-m_)*A4^m_,A4*TAN(RADIANS(tope))) | D4: =DEGREES(ATAN(C4/A4)) | E4: =MIN(DEGREES(ATAN(TAN(RADIANS(Parametros!$E$12-omega*e_base))*(A4/sref)^(Parametros!$B$12-1))),DEGREES(ATAN(TAN(RADIANS(Parametros!$E$13-omega*e_base))*(A4/sref)^(Parametros!$B$13-1))),DEGREES(ATAN(TAN(RADIANS(Parametros!$E$14-omega*e_base))*(A4/sref)^(Parametros!$B$14-1))),DEGREES(ATAN(TAN(RADIANS(Parametros!$E$15-omega*e_base))*(A4/sref)^(Parametros!$B$15-1))),DEGREES(ATAN(TAN(RADIANS(Parametros!$E$16-omega*e_base))*(A4/sref)^(Parametros!$B$16-1)))) | F4: =MAX(DEGREES(ATAN(TAN(RADIANS(Parametros!$F$12-omega*e_base))*(A4/sref)^(Parametros!$B$12-1))),DEGREES(ATAN(TAN(RADIANS(Parametros!$F$13-omega*e_base))*(A4/sref)^(Parametros!$B$13-1))),DEGREES(ATAN(TAN(RADIANS(Parametros!$F$14-omega*e_base))*(A4/sref)^(Parametros!$B$14-1))),DEGREES(ATAN(TAN(RADIANS(Parametros!$F$15-omega*e_base))*(A4/sref)^(Parametros!$B$15-1))),DEGREES(ATAN(TAN(RADIANS(Parametros!$F$16-omega*e_base))*(A4/sref)^(Parametros!$B$16-1)))) | G4: =A4*TAN(RADIANS(E4)) | H4: =A4*TAN(RADIANS(F4)) | I4: =MIN(TAN(RADIANS(pe0-omega*0.55))*sref^(1-m_)*A4^m_,A4*TAN(RADIANS(tope))) | J4: =MIN(TAN(RADIANS(pe0-omega*0.65))*sref^(1-m_)*A4^m_,A4*TAN(RADIANS(tope))) | K4: =IF(MAX(A4,sv_piso)<=1,e_base-cc_bajo*LOG10(MAX(A4,sv_piso)/sv_piso),e_base-cc_bajo*LOG10(1/sv_piso)-cc_alto*LOG10(A4)) | L4: =MIN(TAN(RADIANS(pe0-omega*K4))*sref^(1-m_)*A4^m_,A4*TAN(RADIANS(tope))) | M4: 0.4482 | N4: =MIN(TAN(RADIANS(pe0-omega*M4))*sref^(1-m_)*A4^m_,A4*TAN(RADIANS(tope))) | O4: =DEGREES(ATAN(TAN(RADIANS(33))*(A4/sref)^(0.9-1))) | P4: =DEGREES(ATAN(1.446*(A4*1000)^0.898/(A4*1000))) | Q4: =A4*TAN(RADIANS(O4)) | R4: =A4*TAN(RADIANS(P4)) | S4: =A4*TAN(RADIANS(37))
A5: 0.05 | B5: con ensayos de Antamina | C5: =MIN(TAN(RADIANS(pe0-omega*e_base))*sref^(1-m_)*A5^m_,A5*TAN(RADIANS(tope))) | D5: =DEGREES(ATAN(C5/A5)) | E5: =MIN(DEGREES(ATAN(TAN(RADIANS(Parametros!$E$12-omega*e_base))*(A5/sref)^(Parametros!$B$12-1))),DEGREES(ATAN(TAN(RADIANS(Parametros!$E$13-omega*e_base))*(A5/sref)^(Parametros!$B$13-1))),DEGREES(ATAN(TAN(RADIANS(Parametros!$E$14-omega*e_base))*(A5/sref)^(Parametros!$B$14-1))),DEGREES(ATAN(TAN(RADIANS(Parametros!$E$15-omega*e_base))*(A5/sref)^(Parametros!$B$15-1))),DEGREES(ATAN(TAN(RADIANS(Parametros!$E$16-omega*e_base))*(A5/sref)^(Parametros!$B$16-1)))) | F5: =MAX(DEGREES(ATAN(TAN(RADIANS(Parametros!$F$12-omega*e_base))*(A5/sref)^(Parametros!$B$12-1))),DEGREES(ATAN(TAN(RADIANS(Parametros!$F$13-omega*e_base))*(A5/sref)^(Parametros!$B$13-1))),DEGREES(ATAN(TAN(RADIANS(Parametros!$F$14-omega*e_base))*(A5/sref)^(Parametros!$B$14-1))),DEGREES(ATAN(TAN(RADIANS(Parametros!$F$15-omega*e_base))*(A5/sref)^(Parametros!$B$15-1))),DEGREES(ATAN(TAN(RADIANS(Parametros!$F$16-omega*e_base))*(A5/sref)^(Parametros!$B$16-1)))) | G5: =A5*TAN(RADIANS(E5)) | H5: =A5*TAN(RADIANS(F5)) | I5: =MIN(TAN(RADIANS(pe0-omega*0.55))*sref^(1-m_)*A5^m_,A5*TAN(RADIANS(tope))) | J5: =MIN(TAN(RADIANS(pe0-omega*0.65))*sref^(1-m_)*A5^m_,A5*TAN(RADIANS(tope))) | K5: =IF(MAX(A5,sv_piso)<=1,e_base-cc_bajo*LOG10(MAX(A5,sv_piso)/sv_piso),e_base-cc_bajo*LOG10(1/sv_piso)-cc_alto*LOG10(A5)) | L5: =MIN(TAN(RADIANS(pe0-omega*K5))*sref^(1-m_)*A5^m_,A5*TAN(RADIANS(tope))) | M5: 0.447 | N5: =MIN(TAN(RADIANS(pe0-omega*M5))*sref^(1-m_)*A5^m_,A5*TAN(RADIANS(tope))) | O5: =DEGREES(ATAN(TAN(RADIANS(33))*(A5/sref)^(0.9-1))) | P5: =DEGREES(ATAN(1.446*(A5*1000)^0.898/(A5*1000))) | Q5: =A5*TAN(RADIANS(O5)) | R5: =A5*TAN(RADIANS(P5)) | S5: =A5*TAN(RADIANS(37))
A6: 0.07 | B6: con ensayos de Antamina | C6: =MIN(TAN(RADIANS(pe0-omega*e_base))*sref^(1-m_)*A6^m_,A6*TAN(RADIANS(tope))) | D6: =DEGREES(ATAN(C6/A6)) | E6: =MIN(DEGREES(ATAN(TAN(RADIANS(Parametros!$E$12-omega*e_base))*(A6/sref)^(Parametros!$B$12-1))),DEGREES(ATAN(TAN(RADIANS(Parametros!$E$13-omega*e_base))*(A6/sref)^(Parametros!$B$13-1))),DEGREES(ATAN(TAN(RADIANS(Parametros!$E$14-omega*e_base))*(A6/sref)^(Parametros!$B$14-1))),DEGREES(ATAN(TAN(RADIANS(Parametros!$E$15-omega*e_base))*(A6/sref)^(Parametros!$B$15-1))),DEGREES(ATAN(TAN(RADIANS(Parametros!$E$16-omega*e_base))*(A6/sref)^(Parametros!$B$16-1)))) | F6: =MAX(DEGREES(ATAN(TAN(RADIANS(Parametros!$F$12-omega*e_base))*(A6/sref)^(Parametros!$B$12-1))),DEGREES(ATAN(TAN(RADIANS(Parametros!$F$13-omega*e_base))*(A6/sref)^(Parametros!$B$13-1))),DEGREES(ATAN(TAN(RADIANS(Parametros!$F$14-omega*e_base))*(A6/sref)^(Parametros!$B$14-1))),DEGREES(ATAN(TAN(RADIANS(Parametros!$F$15-omega*e_base))*(A6/sref)^(Parametros!$B$15-1))),DEGREES(ATAN(TAN(RADIANS(Parametros!$F$16-omega*e_base))*(A6/sref)^(Parametros!$B$16-1)))) | G6: =A6*TAN(RADIANS(E6)) | H6: =A6*TAN(RADIANS(F6)) | I6: =MIN(TAN(RADIANS(pe0-omega*0.55))*sref^(1-m_)*A6^m_,A6*TAN(RADIANS(tope))) | J6: =MIN(TAN(RADIANS(pe0-omega*0.65))*sref^(1-m_)*A6^m_,A6*TAN(RADIANS(tope))) | K6: =IF(MAX(A6,sv_piso)<=1,e_base-cc_bajo*LOG10(MAX(A6,sv_piso)/sv_piso),e_base-cc_bajo*LOG10(1/sv_piso)-cc_alto*LOG10(A6)) | L6: =MIN(TAN(RADIANS(pe0-omega*K6))*sref^(1-m_)*A6^m_,A6*TAN(RADIANS(tope))) | M6: 0.4458 | N6: =MIN(TAN(RADIANS(pe0-omega*M6))*sref^(1-m_)*A6^m_,A6*TAN(RADIANS(tope))) | O6: =DEGREES(ATAN(TAN(RADIANS(33))*(A6/sref)^(0.9-1))) | P6: =DEGREES(ATAN(1.446*(A6*1000)^0.898/(A6*1000))) | Q6: =A6*TAN(RADIANS(O6)) | R6: =A6*TAN(RADIANS(P6)) | S6: =A6*TAN(RADIANS(37))
A7: 0.1 | B7: con ensayos de Antamina | C7: =MIN(TAN(RADIANS(pe0-omega*e_base))*sref^(1-m_)*A7^m_,A7*TAN(RADIANS(tope))) | D7: =DEGREES(ATAN(C7/A7)) | E7: =MIN(DEGREES(ATAN(TAN(RADIANS(Parametros!$E$12-omega*e_base))*(A7/sref)^(Parametros!$B$12-1))),DEGREES(ATAN(TAN(RADIANS(Parametros!$E$13-omega*e_base))*(A7/sref)^(Parametros!$B$13-1))),DEGREES(ATAN(TAN(RADIANS(Parametros!$E$14-omega*e_base))*(A7/sref)^(Parametros!$B$14-1))),DEGREES(ATAN(TAN(RADIANS(Parametros!$E$15-omega*e_base))*(A7/sref)^(Parametros!$B$15-1))),DEGREES(ATAN(TAN(RADIANS(Parametros!$E$16-omega*e_base))*(A7/sref)^(Parametros!$B$16-1)))) | F7: =MAX(DEGREES(ATAN(TAN(RADIANS(Parametros!$F$12-omega*e_base))*(A7/sref)^(Parametros!$B$12-1))),DEGREES(ATAN(TAN(RADIANS(Parametros!$F$13-omega*e_base))*(A7/sref)^(Parametros!$B$13-1))),DEGREES(ATAN(TAN(RADIANS(Parametros!$F$14-omega*e_base))*(A7/sref)^(Parametros!$B$14-1))),DEGREES(ATAN(TAN(RADIANS(Parametros!$F$15-omega*e_base))*(A7/sref)^(Parametros!$B$15-1))),DEGREES(ATAN(TAN(RADIANS(Parametros!$F$16-omega*e_base))*(A7/sref)^(Parametros!$B$16-1)))) | G7: =A7*TAN(RADIANS(E7)) | H7: =A7*TAN(RADIANS(F7)) | I7: =MIN(TAN(RADIANS(pe0-omega*0.55))*sref^(1-m_)*A7^m_,A7*TAN(RADIANS(tope))) | J7: =MIN(TAN(RADIANS(pe0-omega*0.65))*sref^(1-m_)*A7^m_,A7*TAN(RADIANS(tope))) | K7: =IF(MAX(A7,sv_piso)<=1,e_base-cc_bajo*LOG10(MAX(A7,sv_piso)/sv_piso),e_base-cc_bajo*LOG10(1/sv_piso)-cc_alto*LOG10(A7)) | L7: =MIN(TAN(RADIANS(pe0-omega*K7))*sref^(1-m_)*A7^m_,A7*TAN(RADIANS(tope))) | M7: 0.444 | N7: =MIN(TAN(RADIANS(pe0-omega*M7))*sref^(1-m_)*A7^m_,A7*TAN(RADIANS(tope))) | O7: =DEGREES(ATAN(TAN(RADIANS(33))*(A7/sref)^(0.9-1))) | P7: =DEGREES(ATAN(1.446*(A7*1000)^0.898/(A7*1000))) | Q7: =A7*TAN(RADIANS(O7)) | R7: =A7*TAN(RADIANS(P7)) | S7: =A7*TAN(RADIANS(37))
A8: 0.15 | B8: con ensayos de Antamina | C8: =MIN(TAN(RADIANS(pe0-omega*e_base))*sref^(1-m_)*A8^m_,A8*TAN(RADIANS(tope))) | D8: =DEGREES(ATAN(C8/A8)) | E8: =MIN(DEGREES(ATAN(TAN(RADIANS(Parametros!$E$12-omega*e_base))*(A8/sref)^(Parametros!$B$12-1))),DEGREES(ATAN(TAN(RADIANS(Parametros!$E$13-omega*e_base))*(A8/sref)^(Parametros!$B$13-1))),DEGREES(ATAN(TAN(RADIANS(Parametros!$E$14-omega*e_base))*(A8/sref)^(Parametros!$B$14-1))),DEGREES(ATAN(TAN(RADIANS(Parametros!$E$15-omega*e_base))*(A8/sref)^(Parametros!$B$15-1))),DEGREES(ATAN(TAN(RADIANS(Parametros!$E$16-omega*e_base))*(A8/sref)^(Parametros!$B$16-1)))) | F8: =MAX(DEGREES(ATAN(TAN(RADIANS(Parametros!$F$12-omega*e_base))*(A8/sref)^(Parametros!$B$12-1))),DEGREES(ATAN(TAN(RADIANS(Parametros!$F$13-omega*e_base))*(A8/sref)^(Parametros!$B$13-1))),DEGREES(ATAN(TAN(RADIANS(Parametros!$F$14-omega*e_base))*(A8/sref)^(Parametros!$B$14-1))),DEGREES(ATAN(TAN(RADIANS(Parametros!$F$15-omega*e_base))*(A8/sref)^(Parametros!$B$15-1))),DEGREES(ATAN(TAN(RADIANS(Parametros!$F$16-omega*e_base))*(A8/sref)^(Parametros!$B$16-1)))) | G8: =A8*TAN(RADIANS(E8)) | H8: =A8*TAN(RADIANS(F8)) | I8: =MIN(TAN(RADIANS(pe0-omega*0.55))*sref^(1-m_)*A8^m_,A8*TAN(RADIANS(tope))) | J8: =MIN(TAN(RADIANS(pe0-omega*0.65))*sref^(1-m_)*A8^m_,A8*TAN(RADIANS(tope))) | K8: =IF(MAX(A8,sv_piso)<=1,e_base-cc_bajo*LOG10(MAX(A8,sv_piso)/sv_piso),e_base-cc_bajo*LOG10(1/sv_piso)-cc_alto*LOG10(A8)) | L8: =MIN(TAN(RADIANS(pe0-omega*K8))*sref^(1-m_)*A8^m_,A8*TAN(RADIANS(tope))) | M8: 0.441 | N8: =MIN(TAN(RADIANS(pe0-omega*M8))*sref^(1-m_)*A8^m_,A8*TAN(RADIANS(tope))) | O8: =DEGREES(ATAN(TAN(RADIANS(33))*(A8/sref)^(0.9-1))) | P8: =DEGREES(ATAN(1.446*(A8*1000)^0.898/(A8*1000))) | Q8: =A8*TAN(RADIANS(O8)) | R8: =A8*TAN(RADIANS(P8)) | S8: =A8*TAN(RADIANS(37))
A9: 0.2 | B9: con ensayos de Antamina | C9: =MIN(TAN(RADIANS(pe0-omega*e_base))*sref^(1-m_)*A9^m_,A9*TAN(RADIANS(tope))) | D9: =DEGREES(ATAN(C9/A9)) | E9: =MIN(DEGREES(ATAN(TAN(RADIANS(Parametros!$E$12-omega*e_base))*(A9/sref)^(Parametros!$B$12-1))),DEGREES(ATAN(TAN(RADIANS(Parametros!$E$13-omega*e_base))*(A9/sref)^(Parametros!$B$13-1))),DEGREES(ATAN(TAN(RADIANS(Parametros!$E$14-omega*e_base))*(A9/sref)^(Parametros!$B$14-1))),DEGREES(ATAN(TAN(RADIANS(Parametros!$E$15-omega*e_base))*(A9/sref)^(Parametros!$B$15-1))),DEGREES(ATAN(TAN(RADIANS(Parametros!$E$16-omega*e_base))*(A9/sref)^(Parametros!$B$16-1)))) | F9: =MAX(DEGREES(ATAN(TAN(RADIANS(Parametros!$F$12-omega*e_base))*(A9/sref)^(Parametros!$B$12-1))),DEGREES(ATAN(TAN(RADIANS(Parametros!$F$13-omega*e_base))*(A9/sref)^(Parametros!$B$13-1))),DEGREES(ATAN(TAN(RADIANS(Parametros!$F$14-omega*e_base))*(A9/sref)^(Parametros!$B$14-1))),DEGREES(ATAN(TAN(RADIANS(Parametros!$F$15-omega*e_base))*(A9/sref)^(Parametros!$B$15-1))),DEGREES(ATAN(TAN(RADIANS(Parametros!$F$16-omega*e_base))*(A9/sref)^(Parametros!$B$16-1)))) | G9: =A9*TAN(RADIANS(E9)) | H9: =A9*TAN(RADIANS(F9)) | I9: =MIN(TAN(RADIANS(pe0-omega*0.55))*sref^(1-m_)*A9^m_,A9*TAN(RADIANS(tope))) | J9: =MIN(TAN(RADIANS(pe0-omega*0.65))*sref^(1-m_)*A9^m_,A9*TAN(RADIANS(tope))) | K9: =IF(MAX(A9,sv_piso)<=1,e_base-cc_bajo*LOG10(MAX(A9,sv_piso)/sv_piso),e_base-cc_bajo*LOG10(1/sv_piso)-cc_alto*LOG10(A9)) | L9: =MIN(TAN(RADIANS(pe0-omega*K9))*sref^(1-m_)*A9^m_,A9*TAN(RADIANS(tope))) | M9: 0.438 | N9: =MIN(TAN(RADIANS(pe0-omega*M9))*sref^(1-m_)*A9^m_,A9*TAN(RADIANS(tope))) | O9: =DEGREES(ATAN(TAN(RADIANS(33))*(A9/sref)^(0.9-1))) | P9: =DEGREES(ATAN(1.446*(A9*1000)^0.898/(A9*1000))) | Q9: =A9*TAN(RADIANS(O9)) | R9: =A9*TAN(RADIANS(P9)) | S9: =A9*TAN(RADIANS(37))
A10: 0.3 | B10: con ensayos de Antamina | C10: =MIN(TAN(RADIANS(pe0-omega*e_base))*sref^(1-m_)*A10^m_,A10*TAN(RADIANS(tope))) | D10: =DEGREES(ATAN(C10/A10)) | E10: =MIN(DEGREES(ATAN(TAN(RADIANS(Parametros!$E$12-omega*e_base))*(A10/sref)^(Parametros!$B$12-1))),DEGREES(ATAN(TAN(RADIANS(Parametros!$E$13-omega*e_base))*(A10/sref)^(Parametros!$B$13-1))),DEGREES(ATAN(TAN(RADIANS(Parametros!$E$14-omega*e_base))*(A10/sref)^(Parametros!$B$14-1))),DEGREES(ATAN(TAN(RADIANS(Parametros!$E$15-omega*e_base))*(A10/sref)^(Parametros!$B$15-1))),DEGREES(ATAN(TAN(RADIANS(Parametros!$E$16-omega*e_base))*(A10/sref)^(Parametros!$B$16-1)))) | F10: =MAX(DEGREES(ATAN(TAN(RADIANS(Parametros!$F$12-omega*e_base))*(A10/sref)^(Parametros!$B$12-1))),DEGREES(ATAN(TAN(RADIANS(Parametros!$F$13-omega*e_base))*(A10/sref)^(Parametros!$B$13-1))),DEGREES(ATAN(TAN(RADIANS(Parametros!$F$14-omega*e_base))*(A10/sref)^(Parametros!$B$14-1))),DEGREES(ATAN(TAN(RADIANS(Parametros!$F$15-omega*e_base))*(A10/sref)^(Parametros!$B$15-1))),DEGREES(ATAN(TAN(RADIANS(Parametros!$F$16-omega*e_base))*(A10/sref)^(Parametros!$B$16-1)))) | G10: =A10*TAN(RADIANS(E10)) | H10: =A10*TAN(RADIANS(F10)) | I10: =MIN(TAN(RADIANS(pe0-omega*0.55))*sref^(1-m_)*A10^m_,A10*TAN(RADIANS(tope))) | J10: =MIN(TAN(RADIANS(pe0-omega*0.65))*sref^(1-m_)*A10^m_,A10*TAN(RADIANS(tope))) | K10: =IF(MAX(A10,sv_piso)<=1,e_base-cc_bajo*LOG10(MAX(A10,sv_piso)/sv_piso),e_base-cc_bajo*LOG10(1/sv_piso)-cc_alto*LOG10(A10)) | L10: =MIN(TAN(RADIANS(pe0-omega*K10))*sref^(1-m_)*A10^m_,A10*TAN(RADIANS(tope))) | M10: 0.432 | N10: =MIN(TAN(RADIANS(pe0-omega*M10))*sref^(1-m_)*A10^m_,A10*TAN(RADIANS(tope))) | O10: =DEGREES(ATAN(TAN(RADIANS(33))*(A10/sref)^(0.9-1))) | P10: =DEGREES(ATAN(1.446*(A10*1000)^0.898/(A10*1000))) | Q10: =A10*TAN(RADIANS(O10)) | R10: =A10*TAN(RADIANS(P10)) | S10: =A10*TAN(RADIANS(37))
A11: 0.5 | B11: con ensayos de Antamina | C11: =MIN(TAN(RADIANS(pe0-omega*e_base))*sref^(1-m_)*A11^m_,A11*TAN(RADIANS(tope))) | D11: =DEGREES(ATAN(C11/A11)) | E11: =MIN(DEGREES(ATAN(TAN(RADIANS(Parametros!$E$12-omega*e_base))*(A11/sref)^(Parametros!$B$12-1))),DEGREES(ATAN(TAN(RADIANS(Parametros!$E$13-omega*e_base))*(A11/sref)^(Parametros!$B$13-1))),DEGREES(ATAN(TAN(RADIANS(Parametros!$E$14-omega*e_base))*(A11/sref)^(Parametros!$B$14-1))),DEGREES(ATAN(TAN(RADIANS(Parametros!$E$15-omega*e_base))*(A11/sref)^(Parametros!$B$15-1))),DEGREES(ATAN(TAN(RADIANS(Parametros!$E$16-omega*e_base))*(A11/sref)^(Parametros!$B$16-1)))) | F11: =MAX(DEGREES(ATAN(TAN(RADIANS(Parametros!$F$12-omega*e_base))*(A11/sref)^(Parametros!$B$12-1))),DEGREES(ATAN(TAN(RADIANS(Parametros!$F$13-omega*e_base))*(A11/sref)^(Parametros!$B$13-1))),DEGREES(ATAN(TAN(RADIANS(Parametros!$F$14-omega*e_base))*(A11/sref)^(Parametros!$B$14-1))),DEGREES(ATAN(TAN(RADIANS(Parametros!$F$15-omega*e_base))*(A11/sref)^(Parametros!$B$15-1))),DEGREES(ATAN(TAN(RADIANS(Parametros!$F$16-omega*e_base))*(A11/sref)^(Parametros!$B$16-1)))) | G11: =A11*TAN(RADIANS(E11)) | H11: =A11*TAN(RADIANS(F11)) | I11: =MIN(TAN(RADIANS(pe0-omega*0.55))*sref^(1-m_)*A11^m_,A11*TAN(RADIANS(tope))) | J11: =MIN(TAN(RADIANS(pe0-omega*0.65))*sref^(1-m_)*A11^m_,A11*TAN(RADIANS(tope))) | K11: =IF(MAX(A11,sv_piso)<=1,e_base-cc_bajo*LOG10(MAX(A11,sv_piso)/sv_piso),e_base-cc_bajo*LOG10(1/sv_piso)-cc_alto*LOG10(A11)) | L11: =MIN(TAN(RADIANS(pe0-omega*K11))*sref^(1-m_)*A11^m_,A11*TAN(RADIANS(tope))) | M11: 0.4201 | N11: =MIN(TAN(RADIANS(pe0-omega*M11))*sref^(1-m_)*A11^m_,A11*TAN(RADIANS(tope))) | O11: =DEGREES(ATAN(TAN(RADIANS(33))*(A11/sref)^(0.9-1))) | P11: =DEGREES(ATAN(1.446*(A11*1000)^0.898/(A11*1000))) | Q11: =A11*TAN(RADIANS(O11)) | R11: =A11*TAN(RADIANS(P11)) | S11: =A11*TAN(RADIANS(37))
A12: 0.7 | B12: con ensayos de Antamina | C12: =MIN(TAN(RADIANS(pe0-omega*e_base))*sref^(1-m_)*A12^m_,A12*TAN(RADIANS(tope))) | D12: =DEGREES(ATAN(C12/A12)) | E12: =MIN(DEGREES(ATAN(TAN(RADIANS(Parametros!$E$12-omega*e_base))*(A12/sref)^(Parametros!$B$12-1))),DEGREES(ATAN(TAN(RADIANS(Parametros!$E$13-omega*e_base))*(A12/sref)^(Parametros!$B$13-1))),DEGREES(ATAN(TAN(RADIANS(Parametros!$E$14-omega*e_base))*(A12/sref)^(Parametros!$B$14-1))),DEGREES(ATAN(TAN(RADIANS(Parametros!$E$15-omega*e_base))*(A12/sref)^(Parametros!$B$15-1))),DEGREES(ATAN(TAN(RADIANS(Parametros!$E$16-omega*e_base))*(A12/sref)^(Parametros!$B$16-1)))) | F12: =MAX(DEGREES(ATAN(TAN(RADIANS(Parametros!$F$12-omega*e_base))*(A12/sref)^(Parametros!$B$12-1))),DEGREES(ATAN(TAN(RADIANS(Parametros!$F$13-omega*e_base))*(A12/sref)^(Parametros!$B$13-1))),DEGREES(ATAN(TAN(RADIANS(Parametros!$F$14-omega*e_base))*(A12/sref)^(Parametros!$B$14-1))),DEGREES(ATAN(TAN(RADIANS(Parametros!$F$15-omega*e_base))*(A12/sref)^(Parametros!$B$15-1))),DEGREES(ATAN(TAN(RADIANS(Parametros!$F$16-omega*e_base))*(A12/sref)^(Parametros!$B$16-1)))) | G12: =A12*TAN(RADIANS(E12)) | H12: =A12*TAN(RADIANS(F12)) | I12: =MIN(TAN(RADIANS(pe0-omega*0.55))*sref^(1-m_)*A12^m_,A12*TAN(RADIANS(tope))) | J12: =MIN(TAN(RADIANS(pe0-omega*0.65))*sref^(1-m_)*A12^m_,A12*TAN(RADIANS(tope))) | K12: =IF(MAX(A12,sv_piso)<=1,e_base-cc_bajo*LOG10(MAX(A12,sv_piso)/sv_piso),e_base-cc_bajo*LOG10(1/sv_piso)-cc_alto*LOG10(A12)) | L12: =MIN(TAN(RADIANS(pe0-omega*K12))*sref^(1-m_)*A12^m_,A12*TAN(RADIANS(tope))) | M12: 0.4083 | N12: =MIN(TAN(RADIANS(pe0-omega*M12))*sref^(1-m_)*A12^m_,A12*TAN(RADIANS(tope))) | O12: =DEGREES(ATAN(TAN(RADIANS(33))*(A12/sref)^(0.9-1))) | P12: =DEGREES(ATAN(1.446*(A12*1000)^0.898/(A12*1000))) | Q12: =A12*TAN(RADIANS(O12)) | R12: =A12*TAN(RADIANS(P12)) | S12: =A12*TAN(RADIANS(37))
A13: 1 | B13: con ensayos de Antamina | C13: =MIN(TAN(RADIANS(pe0-omega*e_base))*sref^(1-m_)*A13^m_,A13*TAN(RADIANS(tope))) | D13: =DEGREES(ATAN(C13/A13)) | E13: =MIN(DEGREES(ATAN(TAN(RADIANS(Parametros!$E$12-omega*e_base))*(A13/sref)^(Parametros!$B$12-1))),DEGREES(ATAN(TAN(RADIANS(Parametros!$E$13-omega*e_base))*(A13/sref)^(Parametros!$B$13-1))),DEGREES(ATAN(TAN(RADIANS(Parametros!$E$14-omega*e_base))*(A13/sref)^(Parametros!$B$14-1))),DEGREES(ATAN(TAN(RADIANS(Parametros!$E$15-omega*e_base))*(A13/sref)^(Parametros!$B$15-1))),DEGREES(ATAN(TAN(RADIANS(Parametros!$E$16-omega*e_base))*(A13/sref)^(Parametros!$B$16-1)))) | F13: =MAX(DEGREES(ATAN(TAN(RADIANS(Parametros!$F$12-omega*e_base))*(A13/sref)^(Parametros!$B$12-1))),DEGREES(ATAN(TAN(RADIANS(Parametros!$F$13-omega*e_base))*(A13/sref)^(Parametros!$B$13-1))),DEGREES(ATAN(TAN(RADIANS(Parametros!$F$14-omega*e_base))*(A13/sref)^(Parametros!$B$14-1))),DEGREES(ATAN(TAN(RADIANS(Parametros!$F$15-omega*e_base))*(A13/sref)^(Parametros!$B$15-1))),DEGREES(ATAN(TAN(RADIANS(Parametros!$F$16-omega*e_base))*(A13/sref)^(Parametros!$B$16-1)))) | G13: =A13*TAN(RADIANS(E13)) | H13: =A13*TAN(RADIANS(F13)) | I13: =MIN(TAN(RADIANS(pe0-omega*0.55))*sref^(1-m_)*A13^m_,A13*TAN(RADIANS(tope))) | J13: =MIN(TAN(RADIANS(pe0-omega*0.65))*sref^(1-m_)*A13^m_,A13*TAN(RADIANS(tope))) | K13: =IF(MAX(A13,sv_piso)<=1,e_base-cc_bajo*LOG10(MAX(A13,sv_piso)/sv_piso),e_base-cc_bajo*LOG10(1/sv_piso)-cc_alto*LOG10(A13)) | L13: =MIN(TAN(RADIANS(pe0-omega*K13))*sref^(1-m_)*A13^m_,A13*TAN(RADIANS(tope))) | M13: 0.3934 | N13: =MIN(TAN(RADIANS(pe0-omega*M13))*sref^(1-m_)*A13^m_,A13*TAN(RADIANS(tope))) | O13: =DEGREES(ATAN(TAN(RADIANS(33))*(A13/sref)^(0.9-1))) | P13: =DEGREES(ATAN(1.446*(A13*1000)^0.898/(A13*1000))) | Q13: =A13*TAN(RADIANS(O13)) | R13: =A13*TAN(RADIANS(P13)) | S13: =A13*TAN(RADIANS(37))
... A18: 4.6 | B18: con ensayos de Antamina | C18: =MIN(TAN(RADIANS(pe0-omega*e_base))*sref^(1-m_)*A18^m_,A18*TAN(RADIANS(tope))) | D18: =DEGREES(ATAN(C18/A18)) | E18: =MIN(DEGREES(ATAN(TAN(RADIANS(Parametros!$E$12-omega*e_base))*(A18/sref)^(Parametros!$B$12-1))),DEGREES(ATAN(TAN(RADIANS(Parametros!$E$13-omega*e_base))*(A18/sref)^(Parametros!$B$13-1))),DEGREES(ATAN(TAN(RADIANS(Parametros!$E$14-omega*e_base))*(A18/sref)^(Parametros!$B$14-1))),DEGREES(ATAN(TAN(RADIANS(Parametros!$E$15-omega*e_base))*(A18/sref)^(Parametros!$B$15-1))),DEGREES(ATAN(TAN(RADIANS(Parametros!$E$16-omega*e_base))*(A18/sref)^(Parametros!$B$16-1)))) | F18: =MAX(DEGREES(ATAN(TAN(RADIANS(Parametros!$F$12-omega*e_base))*(A18/sref)^(Parametros!$B$12-1))),DEGREES(ATAN(TAN(RADIANS(Parametros!$F$13-omega*e_base))*(A18/sref)^(Parametros!$B$13-1))),DEGREES(ATAN(TAN(RADIANS(Parametros!$F$14-omega*e_base))*(A18/sref)^(Parametros!$B$14-1))),DEGREES(ATAN(TAN(RADIANS(Parametros!$F$15-omega*e_base))*(A18/sref)^(Parametros!$B$15-1))),DEGREES(ATAN(TAN(RADIANS(Parametros!$F$16-omega*e_base))*(A18/sref)^(Parametros!$B$16-1)))) | G18: =A18*TAN(RADIANS(E18)) | H18: =A18*TAN(RADIANS(F18)) | I18: =MIN(TAN(RADIANS(pe0-omega*0.55))*sref^(1-m_)*A18^m_,A18*TAN(RADIANS(tope))) | J18: =MIN(TAN(RADIANS(pe0-omega*0.65))*sref^(1-m_)*A18^m_,A18*TAN(RADIANS(tope))) | K18: =IF(MAX(A18,sv_piso)<=1,e_base-cc_bajo*LOG10(MAX(A18,sv_piso)/sv_piso),e_base-cc_bajo*LOG10(1/sv_piso)-cc_alto*LOG10(A18)) | L18: =MIN(TAN(RADIANS(pe0-omega*K18))*sref^(1-m_)*A18^m_,A18*TAN(RADIANS(tope))) | M18: 0.2541 | N18: =MIN(TAN(RADIANS(pe0-omega*M18))*sref^(1-m_)*A18^m_,A18*TAN(RADIANS(tope))) | O18: =DEGREES(ATAN(TAN(RADIANS(33))*(A18/sref)^(0.9-1))) | P18: =DEGREES(ATAN(1.446*(A18*1000)^0.898/(A18*1000))) | Q18: =A18*TAN(RADIANS(O18)) | R18: =A18*TAN(RADIANS(P18)) | S18: =A18*TAN(RADIANS(37))
A19: 5 | B19: solo base mundial | C19: =MIN(TAN(RADIANS(pe0-omega*e_base))*sref^(1-m_)*A19^m_,A19*TAN(RADIANS(tope))) | D19: =DEGREES(ATAN(C19/A19)) | E19: =MIN(DEGREES(ATAN(TAN(RADIANS(Parametros!$E$12-omega*e_base))*(A19/sref)^(Parametros!$B$12-1))),DEGREES(ATAN(TAN(RADIANS(Parametros!$E$13-omega*e_base))*(A19/sref)^(Parametros!$B$13-1))),DEGREES(ATAN(TAN(RADIANS(Parametros!$E$14-omega*e_base))*(A19/sref)^(Parametros!$B$14-1))),DEGREES(ATAN(TAN(RADIANS(Parametros!$E$15-omega*e_base))*(A19/sref)^(Parametros!$B$15-1))),DEGREES(ATAN(TAN(RADIANS(Parametros!$E$16-omega*e_base))*(A19/sref)^(Parametros!$B$16-1)))) | F19: =MAX(DEGREES(ATAN(TAN(RADIANS(Parametros!$F$12-omega*e_base))*(A19/sref)^(Parametros!$B$12-1))),DEGREES(ATAN(TAN(RADIANS(Parametros!$F$13-omega*e_base))*(A19/sref)^(Parametros!$B$13-1))),DEGREES(ATAN(TAN(RADIANS(Parametros!$F$14-omega*e_base))*(A19/sref)^(Parametros!$B$14-1))),DEGREES(ATAN(TAN(RADIANS(Parametros!$F$15-omega*e_base))*(A19/sref)^(Parametros!$B$15-1))),DEGREES(ATAN(TAN(RADIANS(Parametros!$F$16-omega*e_base))*(A19/sref)^(Parametros!$B$16-1)))) | G19: =A19*TAN(RADIANS(E19)) | H19: =A19*TAN(RADIANS(F19)) | I19: =MIN(TAN(RADIANS(pe0-omega*0.55))*sref^(1-m_)*A19^m_,A19*TAN(RADIANS(tope))) | J19: =MIN(TAN(RADIANS(pe0-omega*0.65))*sref^(1-m_)*A19^m_,A19*TAN(RADIANS(tope))) | K19: =IF(MAX(A19,sv_piso)<=1,e_base-cc_bajo*LOG10(MAX(A19,sv_piso)/sv_piso),e_base-cc_bajo*LOG10(1/sv_piso)-cc_alto*LOG10(A19)) | L19: =MIN(TAN(RADIANS(pe0-omega*K19))*sref^(1-m_)*A19^m_,A19*TAN(RADIANS(tope))) | M19: 0.2433 | N19: =MIN(TAN(RADIANS(pe0-omega*M19))*sref^(1-m_)*A19^m_,A19*TAN(RADIANS(tope))) | O19: =DEGREES(ATAN(TAN(RADIANS(33))*(A19/sref)^(0.9-1))) | P19: =DEGREES(ATAN(1.446*(A19*1000)^0.898/(A19*1000))) | Q19: =A19*TAN(RADIANS(O19)) | R19: =A19*TAN(RADIANS(P19)) | S19: =A19*TAN(RADIANS(37)) | T19: 33
A20: 6 | B20: solo base mundial | C20: =MIN(TAN(RADIANS(pe0-omega*e_base))*sref^(1-m_)*A20^m_,A20*TAN(RADIANS(tope))) | D20: =DEGREES(ATAN(C20/A20)) | E20: =MIN(DEGREES(ATAN(TAN(RADIANS(Parametros!$E$12-omega*e_base))*(A20/sref)^(Parametros!$B$12-1))),DEGREES(ATAN(TAN(RADIANS(Parametros!$E$13-omega*e_base))*(A20/sref)^(Parametros!$B$13-1))),DEGREES(ATAN(TAN(RADIANS(Parametros!$E$14-omega*e_base))*(A20/sref)^(Parametros!$B$14-1))),DEGREES(ATAN(TAN(RADIANS(Parametros!$E$15-omega*e_base))*(A20/sref)^(Parametros!$B$15-1))),DEGREES(ATAN(TAN(RADIANS(Parametros!$E$16-omega*e_base))*(A20/sref)^(Parametros!$B$16-1)))) | F20: =MAX(DEGREES(ATAN(TAN(RADIANS(Parametros!$F$12-omega*e_base))*(A20/sref)^(Parametros!$B$12-1))),DEGREES(ATAN(TAN(RADIANS(Parametros!$F$13-omega*e_base))*(A20/sref)^(Parametros!$B$13-1))),DEGREES(ATAN(TAN(RADIANS(Parametros!$F$14-omega*e_base))*(A20/sref)^(Parametros!$B$14-1))),DEGREES(ATAN(TAN(RADIANS(Parametros!$F$15-omega*e_base))*(A20/sref)^(Parametros!$B$15-1))),DEGREES(ATAN(TAN(RADIANS(Parametros!$F$16-omega*e_base))*(A20/sref)^(Parametros!$B$16-1)))) | G20: =A20*TAN(RADIANS(E20)) | H20: =A20*TAN(RADIANS(F20)) | I20: =MIN(TAN(RADIANS(pe0-omega*0.55))*sref^(1-m_)*A20^m_,A20*TAN(RADIANS(tope))) | J20: =MIN(TAN(RADIANS(pe0-omega*0.65))*sref^(1-m_)*A20^m_,A20*TAN(RADIANS(tope))) | K20: =IF(MAX(A20,sv_piso)<=1,e_base-cc_bajo*LOG10(MAX(A20,sv_piso)/sv_piso),e_base-cc_bajo*LOG10(1/sv_piso)-cc_alto*LOG10(A20)) | L20: =MIN(TAN(RADIANS(pe0-omega*K20))*sref^(1-m_)*A20^m_,A20*TAN(RADIANS(tope))) | M20: 0.2176 | N20: =MIN(TAN(RADIANS(pe0-omega*M20))*sref^(1-m_)*A20^m_,A20*TAN(RADIANS(tope))) | O20: =DEGREES(ATAN(TAN(RADIANS(33))*(A20/sref)^(0.9-1))) | P20: =DEGREES(ATAN(1.446*(A20*1000)^0.898/(A20*1000))) | Q20: =A20*TAN(RADIANS(O20)) | R20: =A20*TAN(RADIANS(P20)) | S20: =A20*TAN(RADIANS(37)) | T20: 33
